Workbook

Sheet Read me
B2: GxP Quality Hub: stage evidence workbook (before and after, all 46 prompts)
B3: Built 26 Oct 2026 from the repository at main a2b4828 (75 commits). All data is synthetic. Figures are repository facts, not claims of business improvement.
B5: What it is | C5: One central sheet that compares the state before each stage with the state after it, for every stage prompt in the FDE spine: 3 pre-flight (0A, 0B, 0C), stages 1 to 42 and the FINAL as-built PRD. That is 46 prompts; 43 of them are numbered (1 to 42 plus FINAL), plus the 3 pre-flight prompts.
B6: How to read it | C6: Sheet 'Stage Evidence (46)': one row per prompt. BEFORE = the state the stage started from. AFTER = what the stage actually produced, quoted from its own artifacts. Verdict comes from the stage's commit message. Files and lines are counted in the stage's output folder on main.
B7: Other sheets | C7: 'Repo Before-After': the repository at the legacy import versus today. 'Behaviour Before-After': measured differences between legacy and hub. 'Verdict Summary': live counts. 'Evidence Files': every artifact file with line count and SHA-256 (first 12 characters). 'Commits': commit to stage map.
B8: Where the evidence lives | C8: Each stage's folder under docs/ in gxp-quality-hub-legacy (docs/NN-name/), plus docs/final-prd/ and .fde/ for prompts and decisions. File names in the evidence index are repo paths.
B9: What 'after' does not mean | C9: A stage that ends CONDITIONAL PASS or BLOCKED did not prove business value. Stages 34 to 36 state that no after-data exists, that no improvement may be claimed, and that ROI is not computable. The release gate is NO-GO (0 of 40 approvals).
B10: Known limits | C10: AFTER text is condensed from each stage's own summary and cross-checked to the artifact names and counts; it is not a substitute for the artifacts. Line counts include every file type in the folder (markdown, JSON, scripts, logs). Stage 15 has nine increment commits; its date is the first one. Update 26 Oct: Stage 44 (an extra stage beyond the 46 prompts, merged after this workbook was built from a2b4828) is recorded on the sheet 'Stage 44 (added)' and in the second block of 'Repo Before-After'. The main sheets still describe a2b4828.

Sheet Stage Evidence (46)
A1: Stage-by-stage evidence: before and after
A2: Source: stage prompts in .fde/stage-prompts, outputs in docs/, commits on main. Synthetic data.
A4: # | B4: Stage | C4: Stage name | D4: Phase | E4: Operating mode | F4: Output folder (docs/) | G4: Commit | H4: Date | I4: Gate verdict | J4: BEFORE (state at stage entry) | K4: AFTER (what the stage produced) | L4: What changed | M4: Open items carried forward | N4: Files | O4: Lines | P4: Evidence kind | Q4: Prompt file
A5: 1 | B5: 0A | C5: Pre-Flight Repository & System Orientation | D5: Pre-flight | E5: DISCOVERY — READ-ONLY | F5: 00-preflight/discovery | G5: 5c086e3 | H5: 2026-10-17 | I5: CONDITIONAL PASS | J5: Legacy repository imported unmodified (a6eb4e8, tag baseline-as-found). Docs claim a 6,000-case baseline. Nobody has mapped the system or its data. | K5: 12 discovery artifacts: orientation, data-flow overview, 8 assumptions and 24 unknowns. Key finding: the shipped data/legacy.sqlite3 holds 125 cases (the test-suite fixture), not 6,000. U-13 (identity of the baseline dataset) blocks Stage 4. | L5: Documented repo with a corrected baseline fact | M5: U-13 baseline identity; U-14 original data snapshot | N5: 12 | O5: 857 | P5: Measured (read-only) | Q5: 00A_Pre-Flight-Repository-and-System-Orientation.md
A6: 2 | B6: 0B | C6: Provisional Operating Contract & Engineering Boundaries | D6: Pre-flight | E6: DESIGN — DOCUMENTATION-ONLY | F6: 00-preflight/operating-contract | G6: cda9867 | H6: 2026-10-17 | I6: CONDITIONAL PASS | J6: No operating contract. The repo's own CI/preflight (verify.yml) is destructive to the default DB, so it cannot be a merge gate. | K6: 12 artifacts: change-control rules, data-use constraints (all data synthetic; >=286 instruction-like strings treated strictly as data), evidence contract. Provisional. | L6: Rules of engagement written down | M6: CI isolation fix; all items PROVISIONAL until Stage 25 | N6: 12 | O6: 864 | P6: Documented | Q6: 00B_Provisional-Operating-Contract-and-Engineering-Boundaries.md
A7: 3 | B7: 0C | C7: Provisional Token Efficiency & AI Economics Envelope | D7: Pre-flight | E7: DESIGN — DOCUMENTATION-ONLY | F7: 00-preflight/ai-economics | G7: 779a914 | H7: 2026-10-17 | I7: CONDITIONAL PASS | J7: No cost or token-economics view of any AI option. | K7: 13 artifacts: scenarios S0-S4 (non-AI and AI); worst-case monthly token spend under USD 137 at every volume tier; cost does not separate AI from non-AI, risk and effort do. All price and effort inputs are dated assumptions. | L7: Cost envelope with ranges, all inputs assumed | M7: Stage 8 decides whether S3/S4 stay applicable | N7: 13 | O7: 832 | P7: Documented | Q7: 00C_Provisional-Token-Efficiency-and-AI-Economics-Envelope.md
A8: 4 | B8: 1 | C8: Engage & Qualify | D8: Frame and baseline | E8: DESIGN — DOCUMENTATION-ONLY | F8: 01-engagement | G8: 664af96 | H8: 2026-10-17 | I8: CONDITIONAL PASS | J8: No engagement frame. Client (Gxp Group) is fictional; no sponsor or real telemetry. | K8: Engagement canvas and go/no-go: CONDITIONAL GO, scoped to a synthetic, documentation-first engagement with no commitment to AI or build. Dinesh Naik is the only approver. | L8: Scope and conditions agreed | M8: Open qualification questions | N8: 7 | O8: 498 | P8: Documented | Q8: 01_Engage-and-Qualify.md
A9: 5 | B9: 2 | C9: Stakeholder Discovery & Authority Confirmation | D9: Frame and baseline | E9: DESIGN — DOCUMENTATION-ONLY | F9: 02-stakeholders | G9: 074fa91 | H9: 2026-10-17 | I9: CONDITIONAL PASS | J9: Roles and authority assumed, not evidenced. | K9: Approval-authority, decision-rights and escalation maps. No 0B approval trigger upgraded to CONFIRMED: only OD-01 and OD-04 carry approval wording. Gaps listed. | L9: Authority evidence graded; gaps exposed | M9: Unowned decisions | N9: 7 | O9: 565 | P9: Documented | Q9: 02_Stakeholder-Discovery-and-Authority-Confirmation.md
A10: 6 | B10: 3 | C10: Frame Problem & Value | D10: Frame and baseline | E10: DESIGN — DOCUMENTATION-ONLY | F10: 03-problem-value | G10: 01900b2 | H10: 2026-10-17 | I10: CONDITIONAL PASS | J10: Symptoms scattered across repo documents; no framed problem. | K10: Problems P-1..P-5, outcome-based business requirements (no technology named), jobs-to-be-done, NFRs, assumptions register. All candidate and unvalidated. | L10: Problem and value hypothesis framed | M10: Requirements not accepted by any stakeholder | N10: 11 | O10: 728 | P10: Documented | Q10: 03_Frame-Problem-and-Value.md
A11: 7 | B11: 4 | C11: Capture Before-AI / Before-Intervention KPIs | D11: Frame and baseline | E11: DISCOVERY — READ-ONLY | F11: 04-baseline-kpis | G11: 429bd26 | H11: 2026-10-17 | I11: CONDITIONAL PASS | J11: No baseline numbers; the 'before' state is unmeasured. | K11: KPI dictionary K-01..K-22 and baseline sheet (frozen-provisional) with 8 evidence classes. 12 data-quality issues found: no closure, evidence or approver timestamps anywhere (blocks K-04, K-05, K-09-EVID); external-reference tables almost entirely unmatched to the 125 cases. | L11: Before-state measured where data allows; blockers named | M11: K-04, K-05, K-09-EVID not computable | N11: 13 | O11: 1318 | P11: Measured (read-only) | Q11: 04_Capture-Before-AI-Before-Intervention-KPIs.md
A12: 8 | B12: 5 | C12: Discover Current Process & Brownfield Landscape | D12: Frame and baseline | E12: DISCOVERY — READ-ONLY | F12: 05-current-state | G12: a8e01cc | H12: 2026-10-17 | I12: CONDITIONAL PASS | J12: No map of the estate or of how work flows. | K12: Brownfield inventory (about 850 lines: Python, one 16-line Java file, one 7-line JS file, one SQL file), workflow and control-point maps. Seven decision points; only three are machine-evaluated and those three rules disagree (Python, JavaScript, night-shift). | L12: Current process and rule conflicts visible | M12: Rule ownership | N12: 10 | O12: 801 | P12: Measured (read-only) | Q12: 05_Discover-Current-Process-and-Brownfield-Landscape.md
A13: 9 | B13: 6 | C13: Root-Cause Analysis | D13: Frame and baseline | E13: DESIGN — DOCUMENTATION-ONLY | F13: 06-root-cause | G13: 3b9876a | H13: 2026-10-17 | I13: CONDITIONAL PASS | J13: Symptoms S1-S7 unexplained. | K13: 16 live hypotheses and 10 rejected; 8 root causes (RC-1..RC-8) confirmed at repo level for control, traceability, consistency and measurability symptoms. Not confirmed as causes of delay or cost: no valid flow-time, volume or cost data. | L13: Causes confirmed, with the limit stated | M13: Delay/cost causes unproven | N13: 8 | O13: 802 | P13: Documented | Q13: 06_Root-Cause-Analysis.md
A14: 10 | B14: 7 | C14: Deep Brownfield Repository Assessment & Behaviour Baseline | D14: Assess and qualify | E14: VALIDATE — EXECUTE & OBSERVE | F14: 07-repo-assessment | G14: 32b051a | H14: 2026-10-17 | I14: CONDITIONAL PASS | J14: No behaviour baseline and no architecture document or ADR set; intent spread across README and notes. | K14: 42 files: three golden JSON captures (HTTP API and gateway 39+16 requests; batch/CLI/Java/JS/SQL 58 keys; library edge cases 9 keys), 17 drift items (5 material), characterization test plan. | L14: Executable behaviour baseline to preserve or justify changing | M14: Golden refresh on other interpreters | N14: 42 | O14: 10230 | P14: Executed and observed | Q14: 07_Deep-Brownfield-Repository-Assessment-and-Behaviour-Baseline.md
A15: 11 | B15: 8 | C15: AI-vs-No-AI Qualification | D15: Assess and qualify | E15: DESIGN — DOCUMENTATION-ONLY | F15: 08-ai-qualification | G15: cb66bc2 | H15: 2026-10-17 | I15: CONDITIONAL PASS | J15: AI assumed to be the answer by the training brief. | K15: Scoring matrix of 10 options and 5 touchpoints; recommendation: No-AI, deterministic core, narrow re-qualifiable AI zone. Approved by Dinesh as OD-08 (2026-10-18). | L15: AI decision made on evidence | M15: RQ-1..RQ-4 reconsideration triggers | N15: 8 | O15: 764 | P15: Documented | Q15: 08_AI-vs-No-AI-Qualification.md
A16: 12 | B16: 9 | C16: Initial PRD / Product Intent | D16: Design | E16: DESIGN — DOCUMENTATION-ONLY | F16: 09-initial-prd | G16: 3036896 | H16: 2026-10-18 | I16: CONDITIONAL PASS | J16: No product intent. | K16: Initial PRD: 10 capabilities (all No-AI) in four layers; 52 functional requirements (43 R1, 9 R2) traced to problems and root causes. | L16: Product intent written and traceable | M16: PRD approval OPD-13 | N16: 10 | O16: 1143 | P16: Documented | Q16: 09_Initial-PRD-Product-Intent.md
... A50: 46 | B50: FINAL | C50: Authoritative Final As-Built PRD | D50: Operate and close | E50: DESIGN — DOCUMENTATION-ONLY | F50: final-prd | G50: 67cf15e | H50: 2026-10-25 | I50: BLOCKED | J50: Many stage documents; no single authoritative as-built view. | K50: Final as-built PRD (20 files): as-built architecture, acceptance evidence map, AI/agent baseline; no roadmap approved; BLOCKED. | L50: One authoritative as-built record | M50: Roadmap approval; release | N50: 20 | O50: 1763 | P50: Documented | Q50: 43_FINAL_Authoritative-Final-As-Built-PRD.md
C52: Totals | N52: =SUM(N5:N50) | O52: =SUM(O5:O50)

Sheet Repo Before-After
A1: Repository before and after the 46 stages
A2: Counted with git on the two commits. 'Change' is a live formula.
A4: Measure | B4: Before (legacy import a6eb4e8) | C4: After (main a2b4828) | D4: Change | E4: Note
A5: Tracked files | B5: 500 | C5: 1882 | D5: =C5-B5 | E5: all file types
A6: Python files | B6: 35 | C6: 404 | D6: =C6-B6 | E6: all .py files
A7: Python lines | B7: 818 | C7: 42187 | D7: =C7-B7 | E7: all .py files
A8: hub/ Python files (new code) | B8: 0 | C8: 204 | D8: =C8-B8 | E8: the No-AI modular monolith, stdlib only
A9: hub/ Python lines | B9: 0 | C9: 17247 | D9: =C9-B9
A10: Python test modules under tests/ | B10: 7 | C10: 140 | D10: =C10-B10 | E10: tests/ holds 155 files and 31,102 lines in total after (all file types)
A11: Python test lines under tests/ | B11: 121 | C11: 21573 | D11: =C11-B11
A12: Files under docs/ | B12: 18 | C12: 978 | D12: =C12-B12 | E12: stage artifacts, evidence and decisions
A13: Commits | B13: 1 | C13: 75 | D13: =C13-B13 | E13: baseline import, then stage commits and orchestrator decision records
A14: Hub regression tests (executed) | B14: 0 | C14: 586 | D14: =C14-B14 | E14: 31 groups, Python 3.14.6, clean main, 25 Oct 2026; 1 skip (python3.9 not installed)
A16: Update after Stage 44 (main e62c9b4, 26 Oct 2026)
A17: Tracked files | C17: 1911 | E17: all file types
A18: Python files | C18: 423 | E18: all .py files
A19: Python lines | C19: 44259 | E19: all .py files
A20: hub/ Python files | C20: 218 | E20: adds hub/ai (11 files) and hub/adapters/azure_openai.py; off by default
A21: hub/ Python lines | C21: 18257
A22: Python test modules under tests/ | C22: 145
A23: Python test lines under tests/ | C23: 22635
A24: Files under docs/ | C24: 988 | E24: adds docs/44-genai-qa
A25: Commits | C25: 76
A26: Hub regression tests (executed) | C26: 613 | E26: 33 groups, 612 ok + 1 skip; Python 3.13 cloud sandbox; Python 3.14 re-run pending

Sheet Behaviour Before-After
A1: Measured behaviour: legacy versus hub (synthetic baseline, seed 4100, 125 cases)
A2: Differences are listed as deviations DV-01..DV-11 and stay 'proposed' until a human approves them. A difference is not an improvement.
A4: Topic | B4: Legacy (before) | C4: Hub / outcome (after) | D4: Stage | E4: Class | F4: Source in repo
A5: Month-end total (DV-01) | B5: 742,956.61 (SQL join fan-out) | C5: 622,826.44 (+19.3 % overstatement in legacy) | D5: 7 / 16 | E5: Parity difference, proposed | F5: docs/07-repo-assessment; docs/16-repo-validation
A6: Replayed partner message (DV-02) | B6: DUPLICATE 64 | C6: NOOP_DUPLICATE 67 / REVISED_CONFLICT | D6: 15 / 16 | E6: Proposed deviation | F6: hub/coexistence/seed_s20.json
A7: Quantity out of range (DV-03) | B7: REJECTED 154 | C7: NEGATIVE_VALUE flag, item kept | D7: 15 | E7: Proposed deviation | F7: hub/coexistence/seed_s20.json
A8: Java blank amounts (DV-04) | B8: silently skipped | C8: UNPARSABLE_AMOUNT quarantine | D8: 15 | E8: Proposed deviation | F8: hub/coexistence/seed_s20.json
A9: JS tolerance with 'abc' or null (DV-05) | B9: accepted by prefix/loose parse | C9: E-POL-INPUT-INVALID | D9: 15 | E9: Proposed deviation | F9: hub/coexistence/seed_s20.json
A10: Feed intake outcomes | B10: 8,567 feed rows; 97.98 % unmatched to cases | C10: 8,109 EXCEPTION, 223 QUARANTINED, 165 VALIDATED; exception queue 8,335; replay delta 0 | D10: 4 / 15 | E10: Observed, sandbox | F10: docs/04-baseline-kpis; docs/15-modernization
A11: Characterization of legacy behaviour | B11: no harness | C11: 134/134 checks green; D5 unexplained = 0 | D11: 15 | E11: Verified in sandbox | F11: docs/15-modernization/behavior-preservation-evidence.md
A12: Mutation gate | B12: legacy suite detects 1 of 15 mutants | C12: harness detects 15 of 15 | D12: 15 | E12: Verified in sandbox | F12: docs/15-modernization
A13: Hub test result at validation | B13: none | C13: 396 ok, 1 skipped, 0 fail over 397 hub methods | D13: 16 | E13: Executed | F13: docs/16-repo-validation
A14: Red-team | B14: not attacked | C14: 11 findings: 0 critical, 1 high (fixed), 6 medium, 4 low; 0 Zone H bypasses | D14: 26 | E14: Executed | F14: docs/26-tevv/red-team-findings.md
A15: Third-party dependencies | B15: not inventoried | C15: 36 imported modules, all standard library | D15: 27 | E15: Scanned | F15: docs/27-hardening/dependency-hardening.md
... A19: ROI / NPV / payback | B19: claims in documents | C19: NOT COMPUTABLE (no volumes, rates or costs) | D19: 36 | E19: Blocked, not invented | F19: docs/36-roi

Sheet Verdict Summary
A1: Verdict summary (live from 'Stage Evidence (46)')
A4: Gate verdict | B4: Stages | C4: Share
A5: CONDITIONAL PASS | B5: =COUNTIF('Stage Evidence (46)'!$I$5:$I$50,A5) | C5: =B5/B$9
A6: BLOCKED | B6: =COUNTIF('Stage Evidence (46)'!$I$5:$I$50,A6) | C6: =B6/B$9
A7: NOT APPLICABLE | B7: =COUNTIF('Stage Evidence (46)'!$I$5:$I$50,A7) | C7: =B7/B$9
A8: PASS | B8: =COUNTIF('Stage Evidence (46)'!$I$5:$I$50,A8) | C8: =B8/B$9
A9: Total | B9: =SUM(B5:B8) | C9: =SUM(C5:C8)
A11: By phase
A12: Phase | B12: Stages | C12: Files | D12: Lines
A13: Pre-flight | B13: =COUNTIF('Stage Evidence (46)'!$D$5:$D$50,A13) | C13: =SUMIF('Stage Evidence (46)'!$D$5:$D$50,A13,'Stage Evidence (46)'!$N$5:$N$50) | D13: =SUMIF('Stage Evidence (46)'!$D$5:$D$50,A13,'Stage Evidence (46)'!$O$5:$O$50)
A14: Frame and baseline | B14: =COUNTIF('Stage Evidence (46)'!$D$5:$D$50,A14) | C14: =SUMIF('Stage Evidence (46)'!$D$5:$D$50,A14,'Stage Evidence (46)'!$N$5:$N$50) | D14: =SUMIF('Stage Evidence (46)'!$D$5:$D$50,A14,'Stage Evidence (46)'!$O$5:$O$50)
A15: Assess and qualify | B15: =COUNTIF('Stage Evidence (46)'!$D$5:$D$50,A15) | C15: =SUMIF('Stage Evidence (46)'!$D$5:$D$50,A15,'Stage Evidence (46)'!$N$5:$N$50) | D15: =SUMIF('Stage Evidence (46)'!$D$5:$D$50,A15,'Stage Evidence (46)'!$O$5:$O$50)
A16: Design | B16: =COUNTIF('Stage Evidence (46)'!$D$5:$D$50,A16) | C16: =SUMIF('Stage Evidence (46)'!$D$5:$D$50,A16,'Stage Evidence (46)'!$N$5:$N$50) | D16: =SUMIF('Stage Evidence (46)'!$D$5:$D$50,A16,'Stage Evidence (46)'!$O$5:$O$50)
A17: Build and validate | B17: =COUNTIF('Stage Evidence (46)'!$D$5:$D$50,A17) | C17: =SUMIF('Stage Evidence (46)'!$D$5:$D$50,A17,'Stage Evidence (46)'!$N$5:$N$50) | D17: =SUMIF('Stage Evidence (46)'!$D$5:$D$50,A17,'Stage Evidence (46)'!$O$5:$O$50)
A18: Engineer and control | B18: =COUNTIF('Stage Evidence (46)'!$D$5:$D$50,A18) | C18: =SUMIF('Stage Evidence (46)'!$D$5:$D$50,A18,'Stage Evidence (46)'!$N$5:$N$50) | D18: =SUMIF('Stage Evidence (46)'!$D$5:$D$50,A18,'Stage Evidence (46)'!$O$5:$O$50)
A19: Prove and release-prepare | B19: =COUNTIF('Stage Evidence (46)'!$D$5:$D$50,A19) | C19: =SUMIF('Stage Evidence (46)'!$D$5:$D$50,A19,'Stage Evidence (46)'!$N$5:$N$50) | D19: =SUMIF('Stage Evidence (46)'!$D$5:$D$50,A19,'Stage Evidence (46)'!$O$5:$O$50)
A20: Measure and govern | B20: =COUNTIF('Stage Evidence (46)'!$D$5:$D$50,A20) | C20: =SUMIF('Stage Evidence (46)'!$D$5:$D$50,A20,'Stage Evidence (46)'!$N$5:$N$50) | D20: =SUMIF('Stage Evidence (46)'!$D$5:$D$50,A20,'Stage Evidence (46)'!$O$5:$O$50)
A21: Operate and close | B21: =COUNTIF('Stage Evidence (46)'!$D$5:$D$50,A21) | C21: =SUMIF('Stage Evidence (46)'!$D$5:$D$50,A21,'Stage Evidence (46)'!$N$5:$N$50) | D21: =SUMIF('Stage Evidence (46)'!$D$5:$D$50,A21,'Stage Evidence (46)'!$O$5:$O$50)

Sheet Evidence Files
A1: Every artifact file produced by the stages (working tree of main)
A2: Hash lets you prove the file you are reading is the one listed here.
A4: Stage | B4: Repo path | C4: Lines | D4: Bytes | E4: SHA-256 (first 12)
A5: 0A | B5: docs/00-preflight/discovery/assumptions-unknowns.md | C5: 84 | D5: 8248 | E5: bb77978337d4
A6: 0A | B6: docs/00-preflight/discovery/data-flow-overview.md | C6: 69 | D6: 9858 | E6: 3655dc10a1e5
A7: 0A | B7: docs/00-preflight/discovery/discovery-summary.md | C7: 109 | D7: 9653 | E7: c89a2cde705a
A8: 0A | B8: docs/00-preflight/discovery/high-level-architecture.md | C8: 80 | D8: 7649 | E8: bdcf74856cc8
A9: 0A | B9: docs/00-preflight/discovery/initial-risk-register.md | C9: 61 | D9: 6616 | E9: 21a72296af46
A10: 0A | B10: docs/00-preflight/discovery/integration-overview.md | C10: 75 | D10: 7137 | E10: 327cff3c5a89
A11: 0A | B11: docs/00-preflight/discovery/repository-overview.md | C11: 58 | D11: 7784 | E11: 7e816966560b
A12: 0A | B12: docs/00-preflight/discovery/security-observability-overview.md | C12: 69 | D12: 6738 | E12: 9b8128d0a7ab
A13: 0A | B13: docs/00-preflight/discovery/system-landscape.md | C13: 75 | D13: 7963 | E13: 07d5f1f69643
A14: 0A | B14: docs/00-preflight/discovery/technology-inventory.md | C14: 56 | D14: 5517 | E14: 14b2aa43711f
A15: 0A | B15: docs/00-preflight/discovery/test-overview.md | C15: 52 | D15: 5742 | E15: 3fed33632333
A16: 0A | B16: docs/00-preflight/discovery/workflow-overview.md | C16: 57 | D16: 7245 | E16: 11731aa0e0fc
... A964: FINAL | B964: docs/final-prd/residual-risk-register.md | C964: 99 | D964: 8500 | E964: bc365d2dfa2e

Sheet Commits
A1: Commit log on main (oldest first)
A4: Commit | B4: Date | C4: Message | D4: Stage
A5: a6eb4e8 | B5: 2026-10-17 | C5: baseline: import legacy gxp-quality-hub repository (unmodified)
A6: b126c56 | B6: 2026-10-17 | C6: chore(fde): add FDE stage system prompts and engagement context
A7: 5c086e3 | B7: 2026-10-17 | C7: stage-0A: pre-flight repository & system orientation v0.1 (CONDITIONAL PASS) | D7: 0A
A8: e3ed6f1 | B8: 2026-10-17 | C8: chore(fde): record orchestrator decisions OD-01..OD-05
A9: cda9867 | B9: 2026-10-17 | C9: stage-0B: provisional operating contract & engineering boundaries v0.1 (CONDITIONAL PASS) | D9: 0B
A10: 779a914 | B10: 2026-10-17 | C10: stage-0C: Provisional token efficiency and AI economics envelope v0.1 (CONDITIONAL PASS) | D10: 0C
A11: 664af96 | B11: 2026-10-17 | C11: stage-1: engage & qualify v0.1 (CONDITIONAL PASS) | D11: 1
A12: 074fa91 | B12: 2026-10-17 | C12: stage-2: Stakeholder discovery and authority confirmation v0.1 (CONDITIONAL PASS) | D12: 2
A13: 01900b2 | B13: 2026-10-17 | C13: stage-3: Problem framing & value hypothesis v0.1 (CONDITIONAL PASS) | D13: 3
A14: 429bd26 | B14: 2026-10-17 | C14: stage-4: Before-AI baseline KPIs frozen-provisional v0.1 (CONDITIONAL PASS) | D14: 4
A15: a8e01cc | B15: 2026-10-17 | C15: stage-5: current process & brownfield landscape v0.1 (CONDITIONAL PASS) | D15: 5
A16: 3b9876a | B16: 2026-10-17 | C16: stage-6: root-cause analysis v0.1 (CONDITIONAL PASS) | D16: 6
A17: 32b051a | B17: 2026-10-17 | C17: stage-7: deep brownfield repo assessment & behaviour baseline v0.1 (CONDITIONAL PASS) | D17: 7
A18: cb66bc2 | B18: 2026-10-17 | C18: stage-8: AI-vs-No-AI qualification, recommend No-AI v0.1 (CONDITIONAL PASS) | D18: 8
A19: d4aebe4 | B19: 2026-10-18 | C19: chore(fde): record OD-08 (Accept No-AI) and OD-09 (baseline = 125 cases, seed 4100)
A20: 3036896 | B20: 2026-10-18 | C20: stage-9: Initial PRD / product intent v0.1 (CONDITIONAL PASS) | D20: 9
A21: d025e50 | B21: 2026-10-18 | C21: stage-10: Target architecture + 18 ADRs (no-AI modular monolith, coexistence) v0.1 (CONDITIONAL PASS) | D21: 10
A22: aceec82 | B22: 2026-10-18 | C22: stage-11: Data, knowledge & context strategy (deterministic, No-AI) v0.1 (CONDITIONAL PASS) | D22: 11
A23: fe2ff53 | B23: 2026-10-18 | C23: stage-12: Spec-driven design (10 features, 241 ACs, OpenAPI+JSON Schema+DDL) v0.1 (CONDITIONAL PASS) | D23: 12
A24: 413b94d | B24: 2026-10-18 | C24: stage-13: requirements-specs-tests-evidence traceability v0.1 (CONDITIONAL PASS) | D24: 13
A25: f4dc40e | B25: 2026-10-18 | C25: stage-14: Transformation/migration plan (9 increments, harness-first, per-capability cutover) v0.1 (CONDITIONAL PASS) | D25: 14
A26: c5b11a2 | B26: 2026-10-18 | C26: chore(fde): record OD-11..OD-13 (Stage 15 entry approvals, defaults, merge policy) | D26: 15
A27: afd0569 | B27: 2026-10-18 | C27: stage-15/inc-01: characterisation harness + hermetic fixtures + mutation gate (#1) | D27: 15
A28: 644ee45 | B28: 2026-10-18 | C28: chore(fde): record OD-14 (INC-01 merged; INC-02 defaults)
A29: 599be31 | B29: 2026-10-18 | C29: stage-15/inc-02: hub skeleton, No-AI/sandbox/egress guards, read-only adapters, deviation register, golden-compare (#2) | D29: 15
A30: 8a01da7 | B30: 2026-10-18 | C30: chore(fde): record OD-15 (INC-02 merged; INC-03 defaults)
A31: d03f27b | B31: 2026-10-18 | C31: stage-15/inc-03: hub DB migrations, access control, audit hash chain, backup/restore, rollback rehearsal 1 (#3) | D31: 15
A32: 2fc56e5 | B32: 2026-10-19 | C32: stage-15-inc04: policy & rule service (rule sets inactive, activation gated) (#4) | D32: 15
A33: 8e422e8 | B33: 2026-10-19 | C33: stage-15-inc05: decision record, crosswalk, backfill (#5) | D33: 15
A34: 1c1a1e3 | B34: 2026-10-19 | C34: stage-15-inc06: data intake (natural-key idempotency, contract validation) (#6) | D34: 15
A35: af1209f | B35: 2026-10-19 | C35: stage-15-inc07: runs and metrics (scheduler off) (#7) | D35: 15
A36: 4e79f4e | B36: 2026-10-20 | C36: stage-15-inc08: loopback HTTP surface, reviewer queue, disposition gate (mode none) (#8) | D36: 15
A37: ad5514f | B37: 2026-10-20 | C37: stage-15-inc09: R2 FTS search and templates; Stage 15 close-out (CONDITIONAL PASS) (#9) | D37: 15
A38: 2c63b07 | B38: 2026-10-20 | C38: chore(fde): record OD-23 (INC-09 merged, Stage 15 closed; speed-ups approved) | D38: 15
A39: 2f318be | B39: 2026-10-20 | C39: stage-16: Validate the Good Repo v0.1 (CONDITIONAL PASS) | D39: 16
A40: 8a8e8db | B40: 2026-10-20 | C40: chore(fde): record OD-24 (Stage 16 accepted; runtime 3.12+ target with 3.10 floor) | D40: 16
A41: 40b2762 | B41: 2026-10-20 | C41: stage-17: Finalise Implementation PRD v0.1 (CONDITIONAL PASS) | D41: 17
A42: dcdd550 | B42: 2026-10-21 | C42: chore(fde): record OD-25 (Stage 17 baseline accepted; PCH-22/31, IC-1..8 approved) | D42: 17
...

Sheet Stage 44 (added)
A1: Stage 44: Optional Azure OpenAI Document Q&A (off by default)
A2: Not one of the 46 prompts. Added 26 Oct 2026 at Dinesh's request. Merged as PR #32, main e62c9b4. Gate: CONDITIONAL PASS.
A4: Item | B4: Detail
A5: BEFORE | B5: The hub was No-AI by decision OD-08. No model path existed; the network was blocked outside hub/adapters; a tripwire tracked zero model calls.
A6: AFTER | B6: hub/ai (grounded, cited, advisory Q&A over hub search) plus hub/adapters/azure_openai.py (the only network client). Off by default (ai.enabled=false), needs an approval reference to enable, synthetic data only, kill switch, budget and rate limits, audit trail. CLI: python -m hub.ai ask|status. No web route.
A7: Where Azure OpenAI plugs in | B7: hub/adapters/azure_openai.py, AzureOpenAIClient.complete. Environment variables AZURE_OPENAI_ENDPOINT, AZURE_OPENAI_DEPLOYMENT, AZURE_OPENAI_API_VERSION, AZURE_OPENAI_API_KEY. Config keys ai.enabled and ai.azure_openai.*.
A8: Evidence | B8: Tests S44 26 ok, E44 1 ok; full hub regression 33 groups green (613 executed, 1 skip); CI green. Local fake Azure server only.
A9: What it does not prove | B9: No real Azure call was made. Not validated for real data. Not a GxP record. Human verification required.
A10: Decision | B10: OD-40 (Dinesh, 26 Oct): document Q&A, off by default and advisory, config placeholders only.
A11: Open (Dinesh) | B11: Real-data use, validation of the model path, approval ref for ai.enabled, first live test, Azure data residency and content filter, proxy handling, web route spec addendum, SOP wording.
A12: Docs | B12: docs/44-genai-qa/ (README, requalification-record, architecture-and-plugin-points, setup-runbook, test-plan-and-evidence, rollback, residual-risks-and-open-decisions).
A13: Commit | B13: e62c9b4 stage-44: Optional Azure OpenAI Document Q&A (off by default) v0.1 (CONDITIONAL PASS) (#32)
